<?xml version="1.0" encoding="utf-8"?>
<robot name="mowen" xmlns:xacro="http://wiki.ros.org/xacro">
    <material name="Green">
        <color rgba="0 0.7 0 1"/>
    </material>
    <material name="White">
        <color rgba="0.7 0.7 0.7 1"/>
    </material>

    <xacro:property name="ns" value="$(arg ns)"/>
    <link name="${ns}/base_footprint"/>

    <xacro:macro name="common_link" params="name material path *origin">
        <link name="${ns}/${name}">
            <visual>
                <geometry>
                    <mesh filename="package://robot_vs/config/mowen_param/meshes/${path}/${name}.STL"/>
                </geometry>
                <origin xyz="0 0 0" rpy="0 0 0"/>
                <material name="${material}"/>
            </visual>
            <collision>
                <geometry>
                    <mesh filename="package://robot_vs/config/mowen_param/meshes/${path}/${name}.STL"/>
                </geometry>
                <origin xyz="0 0 0" rpy="0 0 0"/>
            </collision>
            <xacro:insert_block name="origin"/>
        </link>
    </xacro:macro>

    <xacro:macro name="continuous_joint" params="name parent child xyz rpy axis">
        <joint name="${ns}/${name}" type="continuous">
            <parent link="${ns}/${parent}"/>
            <child link="${ns}/${child}"/>
            <origin xyz="${xyz}" rpy="${rpy}"/>
            <axis xyz="${axis}"/>
            <limit lower="${-pi}" upper="${pi}" effort="100" velocity="1"/>
        </joint>
    </xacro:macro>

    <xacro:macro name="fixed_joint" params="name parent child xyz rpy">
        <joint name="${ns}/${name}" type="fixed">
            <parent link="${ns}/${parent}"/>
            <child link="${ns}/${child}"/>
            <origin xyz="${xyz}" rpy="${rpy}"/>
        </joint>
    </xacro:macro>

    <common_link name="base_link" material="Green" path="mecanum">
        <inertial>
            <origin xyz="0.00498197982182523 5.70233829969297E-05 -0.0121008098068578" rpy="0 0 0"/>
            <mass value="0.486218814966626"/>
            <inertia
                    ixx="0.00196277727666921"
                    ixy="2.50447049446755E-07"
                    ixz="0.000140534767811098"
                    iyy="0.00457256033711368"
                    iyz="2.68618064993882E-07"
                    izz="0.00493927269870476"/>
        </inertial>
    </common_link>
    <fixed_joint name="base_joint" parent="base_footprint" child="base_link" xyz="0.0 0.0 0.0815" rpy="0 0 0"/>

    <!-- ======================================== -->
    <!-- 新增：激光雷达laser_link和固定关节 -->
    <!-- ======================================== -->
    <!-- 3. 激光雷达link（用common_link宏，material和path根据你的实际情况改，没有STL的话可以留空或简化） -->
    <common_link name="laser_link" material="White" path="mecanum">
        <!-- 如果没有激光雷达的STL文件，可以把visual和collision标签简化成简单的几何体，比如圆柱 -->
        <!-- 这里先保留你的common_link结构，没有STL的话RViz里不会显示激光雷达模型，但不影响TF和导航 -->
    </common_link>

    <!-- 4. 固定关节：连接base_link和laser_link -->
    <!-- 参数和你launch里的static_transform_publisher完全一致：x=0.1, y=0.0, z=0.05, rpy=3.14159265 0.0 0.0 -->
    <fixed_joint name="base_laser_joint" parent="base_link" child="laser_link" xyz="0.1 0.0 0.05" rpy="3.14159265 0.0 0.0"/>
</robot>